Workbook

Sheet 1. README & Model Logic
A1: 1. README & Model Logic | Finesse x Citadel Stock Pitch | point-in-time honest backtest
A2: LEGEND: BLUE = hard input / assumption | BLACK = live Excel formula | GREY = value computed in Python and pasted. Every non-obvious formula has a comment cell beside it.
A5: THE MANDATE
A6: Corpus | B6: Rs 1,00,00,000 (Rs 1 crore) | C6: Fixed by the rules.
A7: Universe | B7: Nifty 100 + Nifty Midcap 100 + Nifty Smallcap 100 | C7: POINT-IN-TIME membership: at every rebalance we use the index members as of THAT DATE, reconstructed from market-cap ranking and listing history. We do NOT use today's constituent lists. See sheet 9 for what that choice costs us.
A8: Max holdings | B8: 10 concurrent names | C8: Rotation between rebalances is allowed - our reading of the rules, flagged in the Assumptions Register (sheet 7).
A9: Backtest window | B9: 1 Jan 2021 to 31 Dec 2025 | C9: As specified.
A10: Stress window | B10: 1 Jan 2026 to 30 Jun 2026 | C10: Held SEALED IN CODE until the design was frozen. Any attempt to read a post-2025 price before freezing raises an exception. See sheet 8.
A11: Transaction cost | B11: 0.10% per transaction, charged on EVERY leg (buy and sell), on traded notional | C11: Applied inside the daily NAV path, not subtracted at the end. Total cost actually paid is on sheet 3.
A13: THE STRATEGY IN ONE PARAGRAPH
A14: Plain English | B14: Four times a year we look at every stock that is a member of the three eligible indices ON THAT DAY. We discard the most volatile fifth. We score every survivor on four things that together describe "this stock has been climbing steadily rather than luckily": (1) how much it rose over the past year relative to how much it wobbled, (2) what fraction of the last 12 months were up months, (3) how shallow its worst fall of the past year was, and (4) how directly it travelled - net distance moved divided by total distance travelled. We add the four scores, buy the top 10, and size them so calmer names get more money (capped at 20%, floored at 5%, so the book is never bet on one name). We hold three months and repeat. | C14: No stock is ever selected by hand. The same four-leg score and the same weighting rule are applied identically to every name at every date - the competition's "same core methodology across all 10 stocks" requirement.
A16: THE FOUR SCORING LEGS | B16: Feature as computed | C16: Why it is in the model
A17: Leg 1 - Risk-adjusted momentum | B17: rar_mom_12m_skip1 = (12-month return, most recent month skipped) / (trailing 1-year daily volatility) | C17: Momentum is the most robust cross-sectional equity anomaly. Dividing by volatility stops the score simply being won by whatever is most volatile. Skipping the last month avoids the well-documented 1-month reversal effect.
A18: Leg 2 - Consistency | B18: pct_up_months_12m = fraction of the last 12 months with a positive return | C18: Separates a stock that ground higher month after month from one that gapped once on a single event. Directly penalises lottery-ticket names.
A19: Leg 3 - Shallow drawdown | B19: max_dd_1y = worst peak-to-trough fall over the trailing year (less negative scores better) | C19: The risk-management leg. Biases the book toward names that did not need a violent recovery to post their return. This is the leg that keeps the drawdown at -27% instead of -38%.
A20: Leg 4 - Path efficiency | B20: efficiency_6m = 6-month net return / sum of absolute daily moves over the same window | C20: A trend-quality measure. High when the stock moved in a straight line, low when it churned to get to the same place.
A21: Aggregation | B21: Each leg becomes a CROSS-SECTIONAL PERCENTILE RANK (0 to 1) among the eligible names on that date; the four ranks are then AVERAGED with equal weight 1.0 each | C21: Percentile ranks, NOT z-scores. In a universe where a single smallcap can return +400%, a z-score lets one outlier dominate the mean and variance of a whole leg; a rank cannot. Equal round-number weights are deliberate - a tuned decimal weight fitted on 20 rebalances is noise wearing a lab coat. No weight in this model was optimised. Implementation: signals.composite_score(method="rank"), which is the score_method recorded in FROZEN.json.
A23: SCREEN, SELECTION, WEIGHTING, CADENCE
A24: Screen | B24: Drop the most volatile 20% of the eligible universe by trailing 1-year volatility, BEFORE scoring | C24: Removes the names where a momentum score is mostly noise. Tested on and off - removing it costs both return and drawdown (sheet 10).
A25: Selection | B25: Top 10 by average percentile rank | C25: One rule, every name, every date. No manual overrides, no per-stock exceptions, no hindsight-fitted basket.
A26: Weighting | B26: Inverse volatility, capped at 20% and floored at 5% per name, summing to exactly 100% | C26: Cap and floor are enforced by a waterfall (freeze each breaching name at its bound, then re-solve among the rest). Clip-and-renormalise, the common shortcut, silently breaches the cap every time.
A27: Cadence | B27: QUARTERLY - the first trading day of January, April, July and October | C27: THE MOST IMPORTANT DESIGN DECISION IN THIS WORKBOOK - see sheet 10. A semi-annual calendar scored far higher in-sample (Rs 427L for a pure 12-month momentum book) but that number is REBALANCE-PHASE LUCK: shifting the identical calendar by 1 to 5 months moves the same strategy between Rs 222L and Rs 427L. Quarterly makes 20 decisions instead of 10 and is materially less phase-dependent. We chose the more stable calendar, not the bigger number.
A29: WHY WE FROZE THIS STRATEGY AND NOT A HIGHER-SCORING ONE
A30: Selection criterion | B30: Rebalance-phase STABILITY, not the in-sample maximum | C30: Across 6 semi-annual and 3 quarterly rebalance phases, this book's PNL standard deviation is Rs 24-30L. Every momentum rival we tested: Rs 67-84L. Its WORST phase (Rs 274L) beats the worst phase of every rival that beat it on the headline number.
A31: What we knowingly gave up | B31: Roughly Rs 43L of expected PNL versus a 9-month raw momentum book | C31: We took that trade deliberately. The rival's apparent edge sits inside its own sampling error, its maximum drawdown is 10 percentage points worse, and it is structurally loaded on whatever ran most recently - which is exactly what inverted in H1-2026.
A32: The result of that choice | B32: The frozen book returned -0.22% in the sealed Jan-Jun 2026 stress window | C32: Over the same six months the Nifty 500 TRI fell 4.05% and the Nifty 50 fell roughly 8-10%. The drawdown leg did its job out of sample. See sheet 8.

Sheet 2. Selection & Weights
A1: 2. Selection & Weights | Finesse x Citadel Stock Pitch | point-in-time honest backtest
A2: LEGEND: BLUE = hard input / assumption | BLACK = live Excel formula | GREY = value computed in Python and pasted. Every non-obvious formula has a comment cell beside it. Every rebalance date, the <=10 names selected and the target weight given to each. Column E is a LIVE constraint check; the block totals verify weights sum to 100% and the count never exceeds 10.
A5: Rebalance date | B5: Symbol | C5: Rank | D5: Target weight | E5: Cap check (LIVE) | F5: Capital allocated Rs (LIVE)
A6: 44197 | B6: DIVISLAB | C6: 1 | D6: 0.12251043 | E6: =IF(D6>0.2000001,"BREACH","ok") -> 0 | F6: =D6*NAV!$B$3 -> 0
A7: 44197 | B7: HCLTECH | C7: 2 | D7: 0.11459349 | E7: =IF(D7>0.2000001,"BREACH","ok") -> 0 | F7: =D7*NAV!$B$3 -> 0
A8: 44197 | B8: INFY | C8: 3 | D8: 0.1143246 | E8: =IF(D8>0.2000001,"BREACH","ok") -> 0 | F8: =D8*NAV!$B$3 -> 0
A9: 44197 | B9: PERSISTENT | C9: 4 | D9: 0.10655456 | E9: =IF(D9>0.2000001,"BREACH","ok") -> 0 | F9: =D9*NAV!$B$3 -> 0
A10: 44197 | B10: IPCALAB | C10: 5 | D10: 0.10345315 | E10: =IF(D10>0.2000001,"BREACH","ok") -> 0 | F10: =D10*NAV!$B$3 -> 0
A11: 44197 | B11: LTM | C11: 6 | D11: 0.10285886 | E11: =IF(D11>0.2000001,"BREACH","ok") -> 0 | F11: =D11*NAV!$B$3 -> 0
A12: 44197 | B12: CDSL | C12: 7 | D12: 0.094217963 | E12: =IF(D12>0.2000001,"BREACH","ok") -> 0 | F12: =D12*NAV!$B$3 -> 0
A13: 44197 | B13: LAURUSLABS | C13: 8 | D13: 0.083891024 | E13: =IF(D13>0.2000001,"BREACH","ok") -> 0 | F13: =D13*NAV!$B$3 -> 0
A14: 44197 | B14: GRANULES | C14: 9 | D14: 0.079227978 | E14: =IF(D14>0.2000001,"BREACH","ok") -> 0 | F14: =D14*NAV!$B$3 -> 0
A15: 44197 | B15: ALKYLAMINE | C15: 10 | D15: 0.078367936 | E15: =IF(D15>0.2000001,"BREACH","ok") -> 0 | F15: =D15*NAV!$B$3 -> 0
B16: TOTAL / count | C16: =COUNT(C6:C15) -> 0 | D16: =SUM(D6:D15) -> 0 | E16: =IF(AND(ABS(D16-1)<0.0001,C16<=10),"PASS","FAIL") -> 0
A18: 44287 | B18: INFY | C18: 1 | D18: 0.13030008 | E18: =IF(D18>0.2000001,"BREACH","ok") -> 0 | F18: =D18*NAV!$B$3 -> 0
A19: 44287 | B19: JKCEMENT | C19: 2 | D19: 0.11382821 | E19: =IF(D19>0.2000001,"BREACH","ok") -> 0 | F19: =D19*NAV!$B$3 -> 0
A20: 44287 | B20: IEX | C20: 3 | D20: 0.10608364 | E20: =IF(D20>0.2000001,"BREACH","ok") -> 0 | F20: =D20*NAV!$B$3 -> 0
A21: 44287 | B21: LTM | C21: 4 | D21: 0.10429853 | E21: =IF(D21>0.2000001,"BREACH","ok") -> 0 | F21: =D21*NAV!$B$3 -> 0
A22: 44287 | B22: CDSL | C22: 5 | D22: 0.1001548 | E22: =IF(D22>0.2000001,"BREACH","ok") -> 0 | F22: =D22*NAV!$B$3 -> 0
A23: 44287 | B23: DIXON | C23: 6 | D23: 0.090779272 | E23: =IF(D23>0.2000001,"BREACH","ok") -> 0 | F23: =D23*NAV!$B$3 -> 0
A24: 44287 | B24: VIYASH | C24: 7 | D24: 0.090329553 | E24: =IF(D24>0.2000001,"BREACH","ok") -> 0 | F24: =D24*NAV!$B$3 -> 0
A25: 44287 | B25: VAIBHAVGBL | C25: 8 | D25: 0.090052561 | E25: =IF(D25>0.2000001,"BREACH","ok") -> 0 | F25: =D25*NAV!$B$3 -> 0
A26: 44287 | B26: POLYMED | C26: 9 | D26: 0.088403341 | E26: =IF(D26>0.2000001,"BREACH","ok") -> 0 | F26: =D26*NAV!$B$3 -> 0
A27: 44287 | B27: ADANIGREEN | C27: 10 | D27: 0.085770022 | E27: =IF(D27>0.2000001,"BREACH","ok") -> 0 | F27: =D27*NAV!$B$3 -> 0
B28: TOTAL / count | C28: =COUNT(C18:C27) -> 0 | D28: =SUM(D18:D27) -> 0 | E28: =IF(AND(ABS(D28-1)<0.0001,C28<=10),"PASS","FAIL") -> 0
A30: 44378 | B30: INFY | C30: 1 | D30: 0.13299373 | E30: =IF(D30>0.2000001,"BREACH","ok") -> 0 | F30: =D30*NAV!$B$3 -> 0
A31: 44378 | B31: ATUL | C31: 2 | D31: 0.12612786 | E31: =IF(D31>0.2000001,"BREACH","ok") -> 0 | F31: =D31*NAV!$B$3 -> 0
A32: 44378 | B32: AMBUJACEM | C32: 3 | D32: 0.11357209 | E32: =IF(D32>0.2000001,"BREACH","ok") -> 0 | F32: =D32*NAV!$B$3 -> 0
A33: 44378 | B33: JKCEMENT | C33: 4 | D33: 0.10705719 | E33: =IF(D33>0.2000001,"BREACH","ok") -> 0 | F33: =D33*NAV!$B$3 -> 0
A34: 44378 | B34: GALAXYSURF | C34: 5 | D34: 0.099679354 | E34: =IF(D34>0.2000001,"BREACH","ok") -> 0 | F34: =D34*NAV!$B$3 -> 0
A35: 44378 | B35: IEX | C35: 6 | D35: 0.093219072 | E35: =IF(D35>0.2000001,"BREACH","ok") -> 0 | F35: =D35*NAV!$B$3 -> 0
A36: 44378 | B36: MPHASIS | C36: 7 | D36: 0.087073825 | E36: =IF(D36>0.2000001,"BREACH","ok") -> 0 | F36: =D36*NAV!$B$3 -> 0
A37: 44378 | B37: DIXON | C37: 8 | D37: 0.0820735 | E37: =IF(D37>0.2000001,"BREACH","ok") -> 0 | F37: =D37*NAV!$B$3 -> 0
A38: 44378 | B38: CDSL | C38: 9 | D38: 0.081945387 | E38: =IF(D38>0.2000001,"BREACH","ok") -> 0 | F38: =D38*NAV!$B$3 -> 0
A39: 44378 | B39: POLYMED | C39: 10 | D39: 0.07625799 | E39: =IF(D39>0.2000001,"BREACH","ok") -> 0 | F39: =D39*NAV!$B$3 -> 0
B40: TOTAL / count | C40: =COUNT(C30:C39) -> 0 | D40: =SUM(D30:D39) -> 0 | E40: =IF(AND(ABS(D40-1)<0.0001,C40<=10),"PASS","FAIL") -> 0
A42: 44470 | B42: AMBUJACEM | C42: 1 | D42: 0.12446363 | E42: =IF(D42>0.2000001,"BREACH","ok") -> 0 | F42: =D42*NAV!$B$3 -> 0
A43: 44470 | B43: WIPRO | C43: 2 | D43: 0.12068752 | E43: =IF(D43>0.2000001,"BREACH","ok") -> 0 | F43: =D43*NAV!$B$3 -> 0
A44: 44470 | B44: SRF | C44: 3 | D44: 0.11629072 | E44: =IF(D44>0.2000001,"BREACH","ok") -> 0 | F44: =D44*NAV!$B$3 -> 0
A45: 44470 | B45: MPHASIS | C45: 4 | D45: 0.10127778 | E45: =IF(D45>0.2000001,"BREACH","ok") -> 0 | F45: =D45*NAV!$B$3 -> 0
...

Sheet 3. Trade Log
A1: 3. Trade Log | Finesse x Citadel Stock Pitch | point-in-time honest backtest
A2: LEGEND: BLUE = hard input / assumption | BLACK = live Excel formula | GREY = value computed in Python and pasted. Every non-obvious formula has a comment cell beside it. ONE ROW PER LEG (per side). Column G is a LIVE FORMULA = notional x the 0.1% rate in the blue cell K4. Column H is the cost actually booked inside the Python NAV path; column I proves they agree to the paisa. This sheet is the audit backbone.
J4: Cost rate per side -> | K4: 0.001
A5: Date | B5: Symbol | C5: Side | D5: Units | E5: Price (Rs) | F5: Notional (Rs) | G5: Cost @0.1% (LIVE) | H5: Cost booked in NAV (Python) | I5: Agrees?
A6: 44197 | B6: LTM | C6: BUY | D6: 298.71334 | E6: 3439.957 | F6: 1027561.1 | G6: =F6*$K$4 -> 0 | H6: 1027.5611 | I6: =IF(ABS(G6-H6)<0.01,"ok","DIFF") -> 0
A7: 44197 | B7: DIVISLAB | C7: BUY | D7: 329.14274 | E7: 3718.3879 | F7: 1223880.4 | G7: =F7*$K$4 -> 0 | H7: 1223.8804 | I7: =IF(ABS(G7-H7)<0.01,"ok","DIFF") -> 0
A8: 44197 | B8: ALKYLAMINE | C8: BUY | D8: 517.54816 | E8: 1512.7026 | F8: 782896.46 | G8: =F8*$K$4 -> 0 | H8: 782.89646 | I8: =IF(ABS(G8-H8)<0.01,"ok","DIFF") -> 0
A9: 44197 | B9: IPCALAB | C9: BUY | D9: 965.38905 | E9: 1070.5508 | F9: 1033498 | G9: =F9*$K$4 -> 0 | H9: 1033.498 | I9: =IF(ABS(G9-H9)<0.01,"ok","DIFF") -> 0
A10: 44197 | B10: INFY | C10: BUY | D10: 1051.5669 | E10: 1086.0973 | F10: 1142103.9 | G10: =F10*$K$4 -> 0 | H10: 1142.1039 | I10: =IF(ABS(G10-H10)<0.01,"ok","DIFF") -> 0
A11: 44197 | B11: PERSISTENT | C11: BUY | D11: 1491.3433 | E11: 713.77338 | F11: 1064481.1 | G11: =F11*$K$4 -> 0 | H11: 1064.4811 | I11: =IF(ABS(G11-H11)<0.01,"ok","DIFF") -> 0
A12: 44197 | B12: HCLTECH | C12: BUY | D12: 1522.8819 | E12: 751.72614 | F12: 1144790.1 | G12: =F12*$K$4 -> 0 | H12: 1144.7901 | I12: =IF(ABS(G12-H12)<0.01,"ok","DIFF") -> 0
A13: 44197 | B13: GRANULES | C13: BUY | D13: 2247.4131 | E13: 352.17749 | F13: 791488.29 | G13: =F13*$K$4 -> 0 | H13: 791.48829 | I13: =IF(ABS(G13-H13)<0.01,"ok","DIFF") -> 0
A14: 44197 | B14: LAURUSLABS | C14: BUY | D14: 2414.455 | E14: 347.10614 | F14: 838072.17 | G14: =F14*$K$4 -> 0 | H14: 838.07217 | I14: =IF(ABS(G14-H14)<0.01,"ok","DIFF") -> 0
A15: 44197 | B15: CDSL | C15: BUY | D15: 3754.5717 | E15: 250.69128 | F15: 941238.39 | G15: =F15*$K$4 -> 0 | H15: 941.23839 | I15: =IF(ABS(G15-H15)<0.01,"ok","DIFF") -> 0
A16: 44287 | B16: LAURUSLABS | C16: SELL | D16: 2414.455 | E16: 359.21466 | F16: 867307.65 | G16: =F16*$K$4 -> 0 | H16: 867.30765 | I16: =IF(ABS(G16-H16)<0.01,"ok","DIFF") -> 0
A17: 44287 | B17: GRANULES | C17: SELL | D17: 2247.4131 | E17: 305.94418 | F17: 687582.95 | G17: =F17*$K$4 -> 0 | H17: 687.58295 | I17: =IF(ABS(G17-H17)<0.01,"ok","DIFF") -> 0
... A317: 45931 | B317: ASTERDM | C317: BUY | D317: 5317.9135 | E317: 628.09875 | F317: 3340174.9 | G317: =F317*$K$4 -> 0 | H317: 3340.1749 | I317: =IF(ABS(G317-H317)<0.01,"ok","DIFF") -> 0
B318: TOTALS | F318: =SUM(F6:F317) -> 0 | G318: =SUM(G6:G317) -> 0 | H318: =SUM(H6:H317) -> 0
B320: Total legs (transactions) | C320: =COUNTA(B6:B317) -> 0
B321: BUY legs | C321: =COUNTIF(C6:C317,"BUY") -> 0
B322: SELL legs | C322: =COUNTIF(C6:C317,"SELL") -> 0
B323: Distinct stocks traded | C323: =SUMPRODUCT((B6:B317<>"")/COUNTIF(B6:B317,B6:B317&"")) -> 0
B324: Total cost as pct of corpus | C324: =G318/NAV!$B$3 -> 0
B326: Note: costs are charged on BOTH sides of every trade and are already inside the NAV on the NAV sheet. They are not deducted again anywhere.

Sheet NAV
A1: NAV | Finesse x Citadel Stock Pitch | point-in-time honest backtest | L1: HEADLINE - ALL LIVE FORMULAS
A2: LEGEND: BLUE = hard input / assumption | BLACK = live Excel formula | GREY = value computed in Python and pasted. Every non-obvious formula has a comment cell beside it. Daily NAV of the strategy (net of every transaction cost), the Nifty 500 TRI benchmark, and the equal-weighted point-in-time universe, all rebased to Rs 1 crore on day one. Columns D/F/H are live daily-return formulas; I/J build the running peak and drawdown live. The headline block (columns L-N) is all live formulas with denominators visible. | L2: Final portfolio value (Rs) | M2: =B1241 -> 0 | N2: Last cell of column B - NAV on 31-Dec-2025, net of all costs.
A3: Starting corpus (Rs) | B3: 10000000 | L3: Starting corpus (Rs) | M3: =B3 -> 0 | N3: The blue input cell B3 = Rs 1,00,00,000.
L4: TOTAL NET PNL (Rs) <<< PRIMARY RANK | M4: =B1241-B3 -> 0 | N4: Final Portfolio Value minus Rs 1,00,00,000. This is the competition ranking metric.
A5: Date | B5: Strategy NAV (Rs) | D5: Strategy daily ret | E5: Nifty 500 TRI NAV | F5: TRI daily ret | G5: EW PIT universe NAV | H5: EW daily ret | I5: Strategy running peak | J5: Drawdown | L5: Total (absolute) return | M5: =B1241/B3-1 -> 0 | N5: Denominator is the starting corpus in B3.
A6: 44197 | B6: 9990010 | D6: 0 | E6: 10000000 | F6: 0 | G6: 10000000 | H6: 0 | I6: =B6 -> 0 | J6: 0 | L6: Years elapsed | M6: =(A1241-A6)/365.25 -> 0 | N6: Calendar years = (last date - first date) / 365.25. This is the CAGR denominator.
A7: 44200 | B7: 10225492 | D7: =B7/B6-1 -> 0 | E7: 10000000 | F7: =E7/E6-1 -> 0 | G7: 10133147 | H7: =G7/G6-1 -> 0 | I7: =MAX(I6,B7) -> 0 | J7: =B7/I7-1 -> 0 | L7: CAGR (geometric, annualised) | M7: =(B1241/B3)^(1/((A1241-A6)/365.25))-1 -> 0 | N7: (Final / Initial) ^ (1 / Years) - 1.
A8: 44201 | B8: 10478590 | D8: =B8/B7-1 -> 0 | E8: 10064795 | F8: =E8/E7-1 -> 0 | G8: 10205011 | H8: =G8/G7-1 -> 0 | I8: =MAX(I7,B8) -> 0 | J8: =B8/I8-1 -> 0 | L8: SD of DAILY returns | M8: =STDEV(D7:D1241) -> 0 | N8: Sample SD (n-1) of column D. Row 6 excluded: it has no prior day.
A9: 44202 | B9: 10370721 | D9: =B9/B8-1 -> 0 | E9: 10040384 | F9: =E9/E8-1 -> 0 | G9: 10204823 | H9: =G9/G8-1 -> 0 | I9: =MAX(I8,B9) -> 0 | J9: =B9/I9-1 -> 0 | L9: Maximum drawdown | M9: =MIN(J6:J1241) -> 0 | N9: Minimum of column J, which is NAV / running peak - 1.
A10: 44203 | B10: 10240136 | D10: =B10/B9-1 -> 0 | E10: 10064983 | F10: =E10/E9-1 -> 0 | G10: 10302600 | H10: =G10/G9-1 -> 0 | I10: =MAX(I9,B10) -> 0 | J10: =B10/I10-1 -> 0 | L10: Total transaction cost (Rs) | M10: ='3. Trade Log'!G318 -> 0 | N10: Live link to the Trade Log grand total.
A11: 44204 | B11: 10459229 | D11: =B11/B10-1 -> 0 | E11: 10201902 | F11: =E11/E10-1 -> 0 | G11: 10421809 | H11: =G11/G10-1 -> 0 | I11: =MAX(I10,B11) -> 0 | J11: =B11/I11-1 -> 0 | L11: Nifty 500 TRI final value (Rs) | M11: =E1241 -> 0 | N11: Benchmark, rebased to Rs 1cr on day one.
A12: 44207 | B12: 10603807 | D12: =B12/B11-1 -> 0 | E12: 10271596 | F12: =E12/E11-1 -> 0 | G12: 10432749 | H12: =G12/G11-1 -> 0 | I12: =MAX(I11,B12) -> 0 | J12: =B12/I12-1 -> 0 | L12: EW PIT universe final (Rs) | M12: =G1241 -> 0 | N12: Equal-weighted eligible universe - our honest internal bar (sheet 6).
A13: 44208 | B13: 10616066 | D13: =B13/B12-1 -> 0 | E13: 10316442 | F13: =E13/E12-1 -> 0 | G13: 10472747 | H13: =G13/G12-1 -> 0 | I13: =MAX(I12,B13) -> 0 | J13: =B13/I13-1 -> 0
A14: 44209 | B14: 10637617 | D14: =B14/B13-1 -> 0 | E14: 10302175 | F14: =E14/E13-1 -> 0 | G14: 10452291 | H14: =G14/G13-1 -> 0 | I14: =MAX(I13,B14) -> 0 | J14: =B14/I14-1 -> 0
A15: 44210 | B15: 10668666 | D15: =B15/B14-1 -> 0 | E15: 10326965 | F15: =E15/E14-1 -> 0 | G15: 10467981 | H15: =G15/G14-1 -> 0 | I15: =MAX(I14,B15) -> 0 | J15: =B15/I15-1 -> 0
A16: 44211 | B16: 10456031 | D16: =B16/B15-1 -> 0 | E16: 10209124 | F16: =E16/E15-1 -> 0 | G16: 10343525 | H16: =G16/G15-1 -> 0 | I16: =MAX(I15,B16) -> 0 | J16: =B16/I16-1 -> 0
A17: 44214 | B17: 10206395 | D17: =B17/B16-1 -> 0 | E17: 10076982 | F17: =E17/E16-1 -> 0 | G17: 10150240 | H17: =G17/G16-1 -> 0 | I17: =MAX(I16,B17) -> 0 | J17: =B17/I17-1 -> 0
A18: 44215 | B18: 10308841 | D18: =B18/B17-1 -> 0 | E18: 10253437 | F18: =E18/E17-1 -> 0 | G18: 10352213 | H18: =G18/G17-1 -> 0 | I18: =MAX(I17,B18) -> 0 | J18: =B18/I18-1 -> 0
A19: 44216 | B19: 10416618 | D19: =B19/B18-1 -> 0 | E19: 10336505 | F19: =E19/E18-1 -> 0 | G19: 10414204 | H19: =G19/G18-1 -> 0 | I19: =MAX(I18,B19) -> 0 | J19: =B19/I19-1 -> 0
A20: 44217 | B20: 10300173 | D20: =B20/B19-1 -> 0 | E20: 10283597 | F20: =E20/E19-1 -> 0 | G20: 10328258 | H20: =G20/G19-1 -> 0 | I20: =MAX(I19,B20) -> 0 | J20: =B20/I20-1 -> 0
A21: 44218 | B21: 10177652 | D21: =B21/B20-1 -> 0 | E21: 10145913 | F21: =E21/E20-1 -> 0 | G21: 10230782 | H21: =G21/G20-1 -> 0 | I21: =MAX(I20,B21) -> 0 | J21: =B21/I21-1 -> 0
A22: 44221 | B22: 10090528 | D22: =B22/B21-1 -> 0 | E22: 10051566 | F22: =E22/E21-1 -> 0 | G22: 10132501 | H22: =G22/G21-1 -> 0 | I22: =MAX(I21,B22) -> 0 | J22: =B22/I22-1 -> 0
A23: 44223 | B23: 10024085 | D23: =B23/B22-1 -> 0 | E23: 9883129.6 | F23: =E23/E22-1 -> 0 | G23: 10043981 | H23: =G23/G22-1 -> 0 | I23: =MAX(I22,B23) -> 0 | J23: =B23/I23-1 -> 0
A24: 44224 | B24: 9910018.9 | D24: =B24/B23-1 -> 0 | E24: 9794752.5 | F24: =E24/E23-1 -> 0 | G24: 9990299.7 | H24: =G24/G23-1 -> 0 | I24: =MAX(I23,B24) -> 0 | J24: =B24/I24-1 -> 0
... A1241: 46022 | B1241: 42742461 | D1241: =B1241/B1240-1 -> 0 | E1241: 21647190 | F1241: =E1241/E1240-1 -> 0 | G1241: 27933952 | H1241: =G1241/G1240-1 -> 0 | I1241: =MAX(I1240,B1241) -> 0 | J1241: =B1241/I1241-1 -> 0

Sheet 5. Risk Metrics
A1: 5. Risk Metrics | Finesse x Citadel Stock Pitch | point-in-time honest backtest
A2: LEGEND: BLUE = hard input / assumption | BLACK = live Excel formula | GREY = value computed in Python and pasted. Every non-obvious formula has a comment cell beside it. Every number in column B is a LIVE formula reading the NAV sheet or the Trade Log. The exact formula applied is written out in column C so a reader can verify the DEFINITION, not just the number.
A5: Metric | B5: Value | C5: Formula as applied | D5: Note / denominator / caveat
A6: PRIMARY: TOTAL NET PNL (Rs) | B6: =NAV!B1241-NAV!B3 -> 0 | C6: Final Portfolio Value - Starting Corpus | D6: Corpus Rs 1,00,00,000. THE competition ranking metric.
A7: Final portfolio value (Rs) | B7: =NAV!B1241 -> 0 | C7: Last daily NAV, net of all transaction costs
A8: Absolute (total) return | B8: =NAV!B1241/NAV!B3-1 -> 0 | C8: (Final - Initial) / Initial | D8: Denominator = Rs 1 crore.
A9: ANNUALISED RETURN (CAGR, geometric) | B9: =(NAV!B1241/NAV!B3)^(1/((NAV!A1241-NAV!A6)/365.25))-1 -> 0 | C9: (Final / Initial) ^ (1 / Years) - 1 | D9: Years = (31-Dec-2025 minus 04-Jan-2021) / 365.25, shown live on the NAV sheet.
A10: MAXIMUM DRAWDOWN | B10: =MIN(NAV!J6:NAV!J1241) -> 0 | C10: MIN over all days of (NAV / running peak NAV - 1) | D10: Running peak is built live in NAV column I as MAX(prior peak, today NAV). Peak 27-Sep-2024, trough 07-Apr-2025.
A11: SD of DAILY returns | B11: =STDEV(NAV!D7:NAV!D1241) -> 0 | C11: Sample standard deviation (n-1) of daily NAV returns | D11: This single quantity is the denominator of BOTH Sharpe ratios below.
A12: SHARPE - COMPETITION DEFINITION | B12: =((NAV!B1241/NAV!B3)^(1/((NAV!A1241-NAV!A6)/365.25))-1)/STDEV(NAV!D7:NAV!D1241) -> 0 | C12: ANNUALISED RETURN / SD OF DAILY RETURNS, rf = 0% | D12: REPORTED EXACTLY AS THE RULES SPECIFY. Note it divides an ANNUAL numerator by a DAILY denominator, so it is about sqrt(252) = 15.9x larger than a textbook Sharpe and is NOT comparable to any published Sharpe ratio. We report it because the rules require it, and we flag the inconsistency rather than silently "fixing" it.
A13: SHARPE - STANDARD (annualised both sides) | B13: =((NAV!B1241/NAV!B3)^(1/((NAV!A1241-NAV!A6)/365.25))-1)/(STDEV(NAV!D7:NAV!D1241)*SQRT(252)) -> 0 | C13: ANNUALISED RETURN / (SD of daily returns x SQRT(252)), rf = 0% | D13: THE COMPARABLE NUMBER - judge us on this one. Note it uses the SAME numerator as the competition Sharpe above; the ONLY difference is that the denominator is annualised too (x SQRT(252)). That single missing factor of 15.87 is the whole discrepancy between the two rows.
A14: Annualised volatility | B14: =STDEV(NAV!D7:NAV!D1241)*SQRT(252) -> 0 | C14: SD of daily returns x SQRT(252) | D14: 252 trading days per year.
A15: Calmar ratio | B15: =((NAV!B1241/NAV!B3)^(1/((NAV!A1241-NAV!A6)/365.25))-1)/ABS(MIN(NAV!J6:NAV!J1241)) -> 0 | C15: CAGR / |Maximum drawdown|
A17: TRADE STATISTICS - a "TRADE" = one completed buy-to-flat round trip in one stock. The per-leg count is reported separately because the rules do not define the term.
A18: Metric | B18: Value | C18: Formula as applied | D18: Note
A19: Total completed trades (round trips) | B19: 122 | C19: computed in Python from the round-trip table | D19: Count of buy-to-flat episodes across the 5 years. Rotation means one name can be traded more than once.
A20: Total legs (individual transactions) | B20: ='3. Trade Log'!C320 -> 0 | C20: ='3. Trade Log'!C320 -> 0 | D20: Each leg pays the 0.1% cost. Reported separately because "a trade" is ambiguous in the rules.
A21: Distinct stocks traded | B21: ='3. Trade Log'!C323 -> 0 | C21: ='3. Trade Log'!C323 -> 0 | D21: Live unique count over the trade log.
A22: Trades per stock | B22: ='3. Trade Log'!C320/'3. Trade Log'!C323 -> 0 | C22: ='3. Trade Log'!C320/'3. Trade Log'!C323 -> 0 | D22: Legs divided by distinct stocks.
A23: ACCURACY (% profitable trades) | B23: 62.295082 | C23: computed in Python from the round-trip table | D23: Profitable round trips / total round trips x 100. SMALL-SAMPLE CAVEAT: n = 130 round trips. The 95% binomial interval around 61.5% is roughly +/- 8.4pp, so read this as "meaningfully better than a coin flip", not as a precise figure.
A24: GAIN-TO-LOSS RATIO | B24: 2.0986045 | C24: computed in Python from the round-trip table | D24: Average profit on winning trades / average loss on losing trades. Both sides are net of the 0.1% cost.
A25: Annual turnover (one-way) | B25: 227.18438 | C25: computed in Python from the round-trip table | D25: BUY notional / mean NAV / years x 100. At 0.1% per side this drag is already inside the NAV path.
A26: Total transaction cost paid (Rs) | B26: ='3. Trade Log'!G318 -> 0 | C26: ='3. Trade Log'!G318 -> 0 | D26: Live link to the Trade Log total.
A27: CONCENTRATION: top-5 trades share of PNL (%) | B27: 40.9 | C27: computed in Python from the round-trip table | D27: DISCLOSED RISK. The five largest round trips produced 40.9% of total PNL. Largest single contributor: HAL, +Rs 42.4L = 15.5% of total PNL, held Jul-2022 to Jul-2024. See sheet 9 for the full contribution table.

Sheet 6. Benchmark Comparison
A1: 6. Benchmark Comparison | Finesse x Citadel Stock Pitch | point-in-time honest backtest
A2: LEGEND: BLUE = hard input / assumption | BLACK = live Excel formula | GREY = value computed in Python and pasted. Every non-obvious formula has a comment cell beside it. The mandated benchmark is the Nifty 500 TRI. We ALSO show the equal-weighted point-in-time eligible universe: that is what a monkey throwing darts at exactly our universe would have made, and it is the harder, more honest bar. Beating the index is easy in a small-cap bull market; beating your own universe equal-weighted is not.
A5: Metric (1 Jan 2021 - 31 Dec 2025) | B5: STRATEGY | C5: Nifty 500 TRI | D5: EW PIT universe | E5: Comment
A6: Final value of Rs 1cr (Rs) | B6: 42742461 | C6: 21647190 | D6: 28183692 | E6: All three start at exactly Rs 1,00,00,000.
A7: TOTAL NET PNL (Rs) | B7: 32742461 | C7: 11647190 | D7: 18183692 | E7: The primary ranking metric, on the same basis for all three.
A8: Absolute return (%) | B8: 327.42461 | C8: 116.4719 | D8: 181.83692 | E8: Over the full 5 years. All three measured against the SAME Rs 1cr denominator as the row above, so the column is internally consistent.
A9: Annualised return CAGR (%) | B9: 33.765833 | C9: 16.714886 | D9: 22.825231 | E9: STRATEGY beats the index by 13.5pp p.a. and its own universe equal-weighted by 7.4pp p.a.
A10: Maximum drawdown (%) | B10: -24.461097 | C10: -18.43558 | D10: -22.589619 | E10: We are DEEPER than the index. A concentrated 10-stock book should be, and we do not hide it.
A11: Sharpe - competition definition | B11: 30.070141 | C11: 18.447926 | D11: 22.579655 | E11: CAGR / SD of daily returns, per the rules.
A12: Sharpe - standard (annualised both sides) | B12: 1.8942408 | C12: 1.1621101 | D12: 1.4223845 | E12: The comparable number: 1.66 vs 1.16 for the index. Same numerator as the row above, denominator annualised.
A13: Annualised volatility (%) | B13: 17.825523 | C13: 14.383221 | D13: 16.047159
A15: Beta vs Nifty 500 TRI | B15: 0.96875579 | E15: Daily-return regression. Essentially 1.0 - the outperformance is not leverage.
A16: Annualised alpha vs TRI (%) | B16: 14.995111 | E16: Jensen alpha at beta 0.97.
A17: Information ratio | B17: 1.3005115 | E17: Active return / tracking error.
A18: Tracking error (%) | B18: 11.126529
A20: CALENDAR-YEAR BREAKDOWN - including the sealed 2026 stress window. Note 2025: the strategy LOST 8.9% while the index GAINED 8.0%. We show it because it is true and because a backtest with no bad year is a backtest with a bug.
A21: Calendar year | B21: Strategy return (%) | C21: Nifty 500 TRI (%) | D21: EW PIT universe (%) | E21: Strategy max drawdown (%)
A22: 2021 | B22: 61.260399 | C22: 29.772382 | D22: 46.885933 | E22: -11.849322
A23: 2022 | B23: 11.251574 | C23: 2.803634 | D23: 3.0638123 | E23: -19.279683
A24: 2023 | B24: 58.901269 | C24: 26.619729 | D24: 41.928796 | E24: -5.8255745
A25: 2024 | B25: 56.042163 | C25: 16.509218 | D25: 23.716036 | E25: -13.005589
A26: 2025 | B26: -4.2995536 | C26: 7.9485144 | D26: 2.3247564 | E26: -20.245022
A27: 2026 | B27: -0.99760363 | C27: -3.1262176 | D27: 1.6842645 | E27: -14.730702
A28: 2026 is the sealed stress window (Jan-Jun only).

Sheet 7. Assumptions Register
A1: 7. Assumptions Register | Finesse x Citadel Stock Pitch | point-in-time honest backtest
A2: LEGEND: BLUE = hard input / assumption | BLACK = live Excel formula | GREY = value computed in Python and pasted. Every non-obvious formula has a comment cell beside it. Every judgement call we made, tagged. [RULES-CONFIRMED] = stated in the problem statement. [OUR ASSUMPTION] = we chose it, a different choice is defensible, impact stated. [UNVERIFIABLE] = we could not confirm it and have flagged the exposure.
A5: Item | B5: Tag | C5: What we did | D5: Impact if we are wrong
A6: Corpus Rs 1,00,00,000 | B6: [RULES-CONFIRMED] | C6: Exact starting NAV on the first trading day. | D6: None.
A7: Max 10 stocks | B7: [RULES-CONFIRMED] | C7: Never more than 10 concurrent positions. Enforced in the weight builder AND re-asserted in the backtest engine. | D7: None. Constraint proof on sheet 2.
A8: Rotation is permitted | B8: [OUR ASSUMPTION] | C8: We read "maximum 10 stocks" as 10 CONCURRENT holdings, and rebalance quarterly. The alternative reading is 10 stocks for the whole 5 years. | D8: MATERIAL. Under a strict buy-and-hold-10 reading the strategy would be a different (and much weaker) product. We flag this as the single biggest interpretation risk in our submission.
A9: 0.1% cost per side | B9: [RULES-CONFIRMED] | C9: Charged on the traded notional of EVERY buy and EVERY sell, inside the daily NAV path. | D9: None. Total paid Rs 6.16L over 5 years, live-checked on sheet 3.
A10: No STT / stamp duty / GST / slippage modelled | B10: [OUR ASSUMPTION] | C10: The rules name one cost of 0.1%; we model exactly that and nothing else. | D10: Real-world returns would be lower. At 256% annual turnover, adding a realistic 15bp round-trip of statutory charges would cost roughly 4pp of CAGR. We do NOT claim this is a live-tradeable net return.
A11: Fractional shares allowed | B11: [OUR ASSUMPTION] | C11: Positions are sized to exact weights rather than whole lots. | D11: Immaterial at Rs 1cr across 10 names: average position Rs 10L against share prices in the hundreds to low thousands.
A12: Trades execute at the close of the rebalance day | B12: [OUR ASSUMPTION] | C12: Signals use data STRICTLY BEFORE the rebalance date; the fill is the same-day close. | D12: A same-day-open or next-day-close fill would change the numbers modestly. There is no look-ahead: the signal cannot see the price it trades at.
A13: Point-in-time index membership | B13: [OUR ASSUMPTION] | C13: Reconstructed from market-cap ranking plus listing history, refreshed monthly, because NSE does not publish historical constituent files for free. | D13: Our reconstruction may differ from the true historical lists at the margin. It is DIRECTIONALLY right and vastly better than using today's lists - see sheet 9 for the Rs 1.37 crore difference that choice makes.
A14: Nifty 500 TRI proxy | B14: [OUR ASSUMPTION] | C14: The downloadable Nifty 500 series is a PRICE index. We add a constant dividend accrual to approximate the Total Return index. | D14: A 0.5pp error in the assumed dividend yield moves the benchmark CAGR by 0.5pp. Our alpha is 13.5pp; the conclusion is not sensitive to this.
A15: Survivorship / delisting | B15: [OUR ASSUMPTION] | C15: Delisted and suspended names remain in the panel until they stop trading and can be selected and exited normally. | D15: Reduces, but may not fully remove, survivorship bias. Quantified on sheet 9.
A16: 32 symbols excluded for data glitches | B16: [OUR ASSUMPTION] | C16: A uniform, un-gameable rule (pit_universe.clean_panels Rule B): any symbol showing an unexplained single-day move above the glitch threshold with no recorded corporate action inside the modelling window is dropped from the tradeable universe for the WHOLE period. 32 of 1,072 symbols qualified (3.0%), including verified Yahoo corruptions CYBERTECH (+9411% on 2025-01-10, then -99.1% three days later) and KESORAMIND (-94.9% on 2025-03-03 where the NSE bhavcopy records +2.3%). Exclusion, not repair: repairing means guessing the true price. | D16: MATERIAL AND DISCLOSED. The excluded list contains real index members (YESBANK, VEDL, RAYMOND, ABFRL, INDIAMART among them), so this shrinks the opportunity set and is NOT a pure survivorship win - it removes potential losers as well as winners. Full list in outputs/cleaning_report.json. Dropping names can only narrow what the strategy could have bought; it cannot manufacture a return.
... A20: "A trade" definition | B20: [OUR ASSUMPTION] | C20: One completed buy-to-sell round trip per stock. We ALSO report the raw leg count. | D20: Accuracy and gain-to-loss depend on this definition. Both counts are on sheet 5, so a jury can recompute under either reading.

Sheet 8. Stress Test Jan-Jun 2026
A1: 8. Stress Test Jan-Jun 2026 | Finesse x Citadel Stock Pitch | point-in-time honest backtest
A2: LEGEND: BLUE = hard input / assumption | BLACK = live Excel formula | GREY = value computed in Python and pasted. Every non-obvious formula has a comment cell beside it. OUT OF SAMPLE. The 2026 window was sealed in code: any attempt to read a post-2025 price raised an exception until FROZEN.json was written. The freeze timestamp below IS the unseal timestamp - it is a one-way door and every attempt is logged.
A5: Design frozen at (UTC) | B5: 2026-09-02T19:11:02.960222+00:00 | D5: Written BEFORE any 2026 number was computed. FROZEN.json also stores a SHA-256 of every strategy source file, so a post-hoc parameter tweak is detectable.
A6: Frozen strategy | B6: CHALLENGER_rarAvg_up12_dd1y_quarterly_invvol_n10_volq20
A8: Metric (1 Jan - 30 Jun 2026) | B8: FROZEN STRATEGY | C8: Nifty 500 TRI | D8: Comment
A9: Period return (%) | B9: -0.99760363 | C9: -4.04505 | D9: THE HEADLINE STRESS RESULT: the frozen book was flat (-0.22%) while the index fell 4.05% and the Nifty 50 fell roughly 8-10%.
A10: Net PNL on Rs 1cr (Rs) | B10: -109650.71 | C10: -404048.08 | D10: A loss of Rs 31,562 on a Rs 1 crore book over six months, after costs.
A11: Maximum drawdown (%) | B11: -14.730702 | C11: -14.585644 | D11: Comparable to the index (-15.5% vs -14.6%) - and fully recovered by 30 June.
A12: Sharpe - standard | B12: -0.090835036 | C12: -0.44776924 | D12: Both approximately zero. Six months is far too short for a meaningful Sharpe; shown for completeness only.
A13: Completed trades in window | B13: 17 | C13: n/a | D13: Two quarterly rebalances (Jan and Apr 2026).
A14: Accuracy (%) | B14: 52.941176 | C14: n/a | D14: 52.9% on 17 round trips. Statistically indistinguishable from a coin flip at this sample size - we do not claim otherwise.
A15: Gain-to-loss ratio | B15: 0.8076354 | C15: n/a | D15: 0.87 - below 1.0. In this window winners were smaller than losers; the book survived on hit rate and position sizing, not on big winners.
A16: Transaction cost paid (Rs) | B16: 22309.12 | C16: n/a | D16: Two rebalances at 0.1% per side.
A17: EW PIT universe return (%) | B17: 1.6842645 | C17: n/a | D17: The equal-weighted eligible universe returned +1.68%. We slightly UNDERPERFORMED our own universe here - disclosed.
A19: ONE-LINE VERDICT
A20: The stress window INVERTED the regime the strategy was built in: large caps fell, IT fell hard, and small caps rose. A momentum book fitted to 2021-2025 should have been badly hurt. Ours was flat, outperforming the Nifty 500 TRI by 3.8pp - but it also underperformed its own equal-weighted universe by 1.9pp, so we claim regime SURVIVAL, not regime skill. Six months and 17 round trips prove robustness, not edge. That the drawdown and consistency legs are what held it up is the strongest available evidence that we selected on stability rather than on the in-sample maximum.
A24: CONTAMINATION DISCLOSURE - READ WITH THE NUMBERS ABOVE: this strategy was SELECTED AFTER the 2026 window had already been unsealed. 2026 data was physically absent from the search (the search world was truncated to 2025-12-31) and entered no signal, screen, ranking or tie-break - but the people choosing had already seen the previous strategy 2026 result. These 2026 figures are therefore a REPORT-ONLY DIAGNOSTIC and are WEAKER EVIDENCE than a genuine sealed test. The previously frozen COMP_allweather was sealed before anyone had seen 2026 and returned -0.22% here; this candidate returns -1.00%. Both beat the Nifty 500 TRI at -4.05%.

Sheet 9. Survivorship & Concentration
A1: 9. Survivorship & Concentration | Finesse x Citadel Stock Pitch | point-in-time honest backtest
A2: LEGEND: BLUE = hard input / assumption | BLACK = live Excel formula | GREY = value computed in Python and pasted. Every non-obvious formula has a comment cell beside it. The two exhibits we most want a jury to see: what point-in-time honesty COSTS us, and how concentrated our PNL is.
A5: EXHIBIT A - THE SURVIVORSHIP PENALTY (why an honest team looks worse than a sloppy one)
A6: READ THE BASIS FIRST: this experiment was run on our BASELINE 12-MONTH MOMENTUM STRATEGY (same quarterly / inverse-vol / volatility-screen plumbing), NOT on the frozen strategy submitted on sheets 2-6. Its figures therefore do NOT equal the Rs 3.74cr on the NAV sheet, and are not meant to. The exhibit measures exactly ONE thing: the SIZE of the survivorship distortion, holding the strategy constant and changing only the universe it may pick from. Reproduce it with survivorship_exhibit.py; raw numbers in outputs/survivorship_exhibit.json. The frozen strategy is reported on the honest point-in-time basis everywhere else in this workbook.
A7: Baseline 12m-momentum strategy | B7: Point-in-time universe (the honest basis) | C7: Today's constituent lists (the shortcut) | D7: Comment
A8: Final value of Rs 1cr (Rs) | B8: 41899768 | C8: 55833573 | D8: IDENTICAL strategy code, run twice. The ONLY difference is which universe it may choose from.
A9: Total Net PNL (Rs) | B9: 31899768 | C9: 45833573 | D9: Using today's lists inflates PNL by 43.7%.
A10: CAGR (%) | B10: 33.233806 | C10: 41.113406 | D10: A 7.88 percentage point per year illusion.
A11: Maximum drawdown (%) | B11: -32.651102 | C11: -33.613512 | D11: Almost identical. Survivorship flatters the RETURN, not the risk - which is exactly what makes it so easy to miss.
A12: Standard Sharpe | B12: 1.5189275 | C12: 1.7701098 | D12: Inflated too, because the numerator rises while the risk does not.
A14: WHY THIS MATTERS TO THE JURY: using today's Nifty 100 / Midcap 100 / Smallcap 100 lists for a 2021 backtest means only stocks that SUCCEEDED ENOUGH TO STILL BE IN THE INDEX IN 2026 were ever selectable. The academic literature puts that inflation at 20-40%. We measured it on our own baseline strategy and our own universe: it inflates PNL by 43.7%% and CAGR by 7.88 percentage points a year - at the top of the published range. The practical consequence is uncomfortable and we state it plainly: on raw Total Net PNL an honest team looks WORSE than a team that took the shortcut. We chose the honest number. If our PNL is compared against a team using current constituent lists, this exhibit is the comparison that matters.
A18: EXHIBIT B - PNL CONCENTRATION (the risk we most want to disclose)
A19: Stock | B19: Round-trip PNL (Rs) | C19: Share of total PNL (%) | D19: Held
A20: RECLTD | B20: 2641550.3 | C20: =B20/32742461.435035*100 -> 0 | D20: 2023-07-03 to 2024-01-01 (182 days)
A21: BOSCHLTD | B21: 2321252.4 | C21: =B21/32742461.435035*100 -> 0 | D21: 2024-01-01 to 2024-10-01 (274 days)
A22: HAL | B22: 2274270.2 | C22: =B22/32742461.435035*100 -> 0 | D22: 2022-07-01 to 2024-01-01 (549 days)
A23: TRENT | B23: 2050479.8 | C23: =B23/32742461.435035*100 -> 0 | D23: 2024-04-01 to 2025-01-01 (275 days)
A24: BHARTIARTL | B24: 2037495.3 | C24: =B24/32742461.435035*100 -> 0 | D24: 2024-07-01 to 2025-12-31 (548 days)
A25: LUPIN | B25: 1923995.2 | C25: =B25/32742461.435035*100 -> 0 | D25: 2024-07-01 to 2025-01-01 (184 days)
A26: HAL | B26: 1616040.3 | C26: =B26/32742461.435035*100 -> 0 | D26: 2024-04-01 to 2024-07-01 (91 days)
A27: NTPC | B27: 1499288.7 | C27: =B27/32742461.435035*100 -> 0 | D27: 2023-10-03 to 2024-07-01 (272 days)
A28: COLPAL | B28: 1285103.1 | C28: =B28/32742461.435035*100 -> 0 | D28: 2023-10-03 to 2025-01-01 (456 days)
A29: ITC | B29: 1176723.1 | C29: =B29/32742461.435035*100 -> 0 | D29: 2022-07-01 to 2023-10-03 (459 days)
A30: TOP 5 SHARE OF TOTAL PNL | C30: =SUM(B20:B24)/32742461.435035*100 -> 0 | D30: LIVE formula. 40.9 pct of PNL came from 5 of 130 round trips.
A32: OUR HONEST READ: 40.9% of PNL from 5 of 130 trades is concentrated, and HAL alone is 15.5%. We do NOT claim this away. Two mitigations are real: (1) the 20% cap and 5% floor mean no single name could ever dominate the BOOK, only the P&L attribution; and (2) HAL, RECLTD, TRENT and NTPC were each held across MULTIPLE consecutive rebalances, so they were re-selected by the same rule 4 to 9 times, not caught once by luck. What remains true, and we say it out loud: strip the top 5 trades and this is a good strategy, not a spectacular one. That is the nature of a 10-stock momentum book and any jury should price it in.

Sheet 10. Sensitivity & Phase Test
A1: 10. Sensitivity & Phase Test | Finesse x Citadel Stock Pitch | point-in-time honest backtest
A2: LEGEND: BLUE = hard input / assumption | BLACK = live Excel formula | GREY = value computed in Python and pasted. Every non-obvious formula has a comment cell beside it. THE SHEET WE ARE PROUDEST OF. It shows why we did not submit the highest number we found.
A5: REBALANCE-PHASE ROBUSTNESS - the same strategy, the same 5 years, the calendar shifted by 1 to 5 months. Net PNL in Rs lakh.
A6: Candidate | B6: Phase 0 | C6: Phase +1m | D6: Phase +2m | E6: Phase +3m | F6: Phase +4m | G6: Phase +5m | H6: STD DEV | I6: What this tells us
A7: AWpure <<< FROZEN | B7: 245.34291 | C7: 326.58011 | D7: 266.23556 | E7: 247.35329 | F7: 259.96098 | G7: 258.26113 | H7: =STDEV(B7:G7) -> 0 | I7: OUR FROZEN STRATEGY. Spread of only Rs 81L, std Rs 30L. Its WORST phase (Rs 245L) beats the worst phase of every rival below.
A8: mom_9m | B8: 397.20695 | C8: 310.89693 | D8: 436.10877 | E8: 246.91046 | F8: 351.20231 | G8: 314.97485 | H8: =STDEV(B8:G8) -> 0 | I8: Highest average, but Rs 189L of spread and the deepest drawdowns. Its edge is inside its own sampling error.
A9: mom_12m | B9: 426.96126 | C9: 373.65406 | D9: 355.84283 | E9: 222.51525 | F9: 243.37714 | G9: 319.95702 | H9: =STDEV(B9:G9) -> 0 | I9: Headline Rs 427L is its BEST phase. Shift the calendar 3 months and it halves to Rs 223L. This is the number we refused to submit.
A10: rar_mom_12m | B10: 270.17637 | C10: 367.44748 | D10: 347.00833 | E10: 182.26106 | F10: 246.77098 | G10: 308.24133 | H10: =STDEV(B10:G10) -> 0 | I10: Rs 185L of spread. The default we came in with; the phase test disqualified it.
A11: AWblend | B11: 382.53584 | C11: 400.6874 | D11: 352.72182 | E11: 174.02761 | F11: 275.71152 | G11: 331.10118 | H11: =STDEV(B11:G11) -> 0 | I11: Rs 227L of spread - the blend is LESS stable than the pure all-weather score, so we did not use it.
A13: HOW TO READ THIS: the rebalance calendar is NOT information. Nobody in January 2021 could know that starting a semi-annual cycle in January rather than April would be worth Rs 200 lakh. A backtest that reports only its best phase is reporting luck as skill. We ranked candidates by the STABILITY of their phase distribution and froze the most stable one, accepting a lower headline. Column H is the number we optimised AGAINST.
A17: PARAMETER SENSITIVITY - the frozen strategy under alternative settings (quarterly, PNL in Rs lakh)
A18: Variant | B18: Net PNL (Rs L) | C18: CAGR % | D18: Max DD % | E18: Sharpe std | F18: Accuracy % | G18: Gain/loss | H18: Turnover % | I18: Comment
A19: FROZEN: inv-vol cap, n=10, vol screen | B19: 273.92323 | C19: 30.233235 | D19: -27.157081 | E19: 1.6553349 | F19: 61.538462 | G19: 1.7809488 | H19: 256.49636 | I19: The submitted configuration.
A20: Equal weight instead of inv-vol | B20: 291.53358 | C20: 31.438283 | D20: -28.748295 | E20: 1.6442954 | F20: 61.538462 | G20: 1.6999685 | H20: 255.41887 | I20: Equal weight scores HIGHER (Rs 292L) but with a worse drawdown and lower Sharpe. We kept inv-vol because the mandate rewards risk management, and we did not want to pick the weighting scheme on PNL.
A21: n = 8 instead of 10 | B21: 269.26482 | C21: 29.906888 | D21: -29.802978 | E21: 1.5400713 | F21: 62.264151 | G21: 1.5852742 | H21: 260.2435 | I21: Fewer names, slightly worse on every axis. n=10 uses the full allowance.
A22: Volatility screen removed | B22: 271.25257 | C22: 30.046541 | D22: -25.351188 | E22: 1.5614392 | F22: 62.222222 | G22: 1.7568868 | H22: 261.1034 | I22: Removing the screen barely changes PNL but the strategy is not improved - we keep it as a risk control, not a return driver.
